[2025-06-17T07:08:42.730+0000] {taskinstance.py:1103} INFO - Dependencies all met for dep_context=non-requeueable deps ti=<TaskInstance: idx_pipeline.load_idx manual__2025-06-17T07:00:52.189015+00:00 [queued]>
[2025-06-17T07:08:42.750+0000] {taskinstance.py:1103} INFO - Dependencies all met for dep_context=requeueable deps ti=<TaskInstance: idx_pipeline.load_idx manual__2025-06-17T07:00:52.189015+00:00 [queued]>
[2025-06-17T07:08:42.751+0000] {taskinstance.py:1308} INFO - Starting attempt 2 of 2
[2025-06-17T07:08:42.786+0000] {taskinstance.py:1327} INFO - Executing <Task(DockerOperator): load_idx> on 2025-06-17 07:00:52.189015+00:00
[2025-06-17T07:08:42.797+0000] {standard_task_runner.py:57} INFO - Started process 1475 to run task
[2025-06-17T07:08:42.805+0000] {standard_task_runner.py:84} INFO - Running: ['***', 'tasks', 'run', 'idx_pipeline', 'load_idx', 'manual__2025-06-17T07:00:52.189015+00:00', '--job-id', '44', '--raw', '--subdir', 'DAGS_FOLDER/idx_pipeline_dag.py', '--cfg-path', '/tmp/tmpiu1dvwv2']
[2025-06-17T07:08:42.808+0000] {standard_task_runner.py:85} INFO - Job 44: Subtask load_idx
[2025-06-17T07:08:42.922+0000] {task_command.py:410} INFO - Running <TaskInstance: idx_pipeline.load_idx manual__2025-06-17T07:00:52.189015+00:00 [running]> on host 96e228aebcb0
[2025-06-17T07:08:43.167+0000] {taskinstance.py:1547} INFO - Exporting env vars: AIRFLOW_CTX_DAG_OWNER='***' AIRFLOW_CTX_DAG_ID='idx_pipeline' AIRFLOW_CTX_TASK_ID='load_idx' AIRFLOW_CTX_EXECUTION_DATE='2025-06-17T07:00:52.189015+00:00' AIRFLOW_CTX_TRY_NUMBER='2' AIRFLOW_CTX_DAG_RUN_ID='manual__2025-06-17T07:00:52.189015+00:00'
[2025-06-17T07:08:43.235+0000] {docker.py:334} INFO - Starting docker container from image bigdata-pipeline:latest
[2025-06-17T07:08:43.985+0000] {docker.py:403} INFO - python: can't open file '/app/idx-load.py': [Errno 2] No such file or directory
[2025-06-17T07:08:44.585+0000] {taskinstance.py:1824} ERROR - Task failed with exception
Traceback (most recent call last):
  File "/home/airflow/.local/lib/python3.7/site-packages/airflow/providers/docker/operators/docker.py", line 478, in execute
    return self._run_image()
  File "/home/airflow/.local/lib/python3.7/site-packages/airflow/providers/docker/operators/docker.py", line 351, in _run_image
    return self._run_image_with_mounts(self.mounts, add_tmp_variable=False)
  File "/home/airflow/.local/lib/python3.7/site-packages/airflow/providers/docker/operators/docker.py", line 412, in _run_image_with_mounts
    raise AirflowException(f"Docker container failed: {repr(result)} lines {joined_log_lines}")
airflow.exceptions.AirflowException: Docker container failed: {'StatusCode': 2} lines python: can't open file '/app/idx-load.py': [Errno 2] No such file or directory
[2025-06-17T07:08:44.594+0000] {taskinstance.py:1350} INFO - Marking task as FAILED. dag_id=idx_pipeline, task_id=load_idx, execution_date=20250617T070052, start_date=20250617T070842, end_date=20250617T070844
[2025-06-17T07:08:44.628+0000] {standard_task_runner.py:109} ERROR - Failed to execute job 44 for task load_idx (Docker container failed: {'StatusCode': 2} lines python: can't open file '/app/idx-load.py': [Errno 2] No such file or directory; 1475)
[2025-06-17T07:08:44.668+0000] {local_task_job_runner.py:225} INFO - Task exited with return code 1
[2025-06-17T07:08:44.710+0000] {taskinstance.py:2653} INFO - 0 downstream tasks scheduled from follow-on schedule check
