[2025-06-17T10:40:31.556+0000] {taskinstance.py:1103} INFO - Dependencies all met for dep_context=non-requeueable deps ti=<TaskInstance: idx_pipeline.extract_idx manual__2025-06-17T10:38:41.077124+00:00 [queued]>
[2025-06-17T10:40:31.580+0000] {taskinstance.py:1103} INFO - Dependencies all met for dep_context=requeueable deps ti=<TaskInstance: idx_pipeline.extract_idx manual__2025-06-17T10:38:41.077124+00:00 [queued]>
[2025-06-17T10:40:31.581+0000] {taskinstance.py:1308} INFO - Starting attempt 2 of 2
[2025-06-17T10:40:31.628+0000] {taskinstance.py:1327} INFO - Executing <Task(DockerOperator): extract_idx> on 2025-06-17 10:38:41.077124+00:00
[2025-06-17T10:40:31.638+0000] {standard_task_runner.py:57} INFO - Started process 154 to run task
[2025-06-17T10:40:31.643+0000] {standard_task_runner.py:84} INFO - Running: ['***', 'tasks', 'run', 'idx_pipeline', 'extract_idx', 'manual__2025-06-17T10:38:41.077124+00:00', '--job-id', '69', '--raw', '--subdir', 'DAGS_FOLDER/idx_pipeline_dag.py', '--cfg-path', '/tmp/tmpntgjcb9l']
[2025-06-17T10:40:31.645+0000] {standard_task_runner.py:85} INFO - Job 69: Subtask extract_idx
[2025-06-17T10:40:31.740+0000] {task_command.py:410} INFO - Running <TaskInstance: idx_pipeline.extract_idx manual__2025-06-17T10:38:41.077124+00:00 [running]> on host 790f4cde8a0c
[2025-06-17T10:40:31.943+0000] {taskinstance.py:1547} INFO - Exporting env vars: AIRFLOW_CTX_DAG_OWNER='***' AIRFLOW_CTX_DAG_ID='idx_pipeline' AIRFLOW_CTX_TASK_ID='extract_idx' AIRFLOW_CTX_EXECUTION_DATE='2025-06-17T10:38:41.077124+00:00' AIRFLOW_CTX_TRY_NUMBER='2' AIRFLOW_CTX_DAG_RUN_ID='manual__2025-06-17T10:38:41.077124+00:00'
[2025-06-17T10:40:32.004+0000] {docker.py:334} INFO - Starting docker container from image bigdata-pipeline:latest
[2025-06-17T10:40:32.026+0000] {taskinstance.py:1824} ERROR - Task failed with exception
Traceback (most recent call last):
  File "/home/airflow/.local/lib/python3.7/site-packages/docker/api/client.py", line 268, in _raise_for_status
    response.raise_for_status()
  File "/home/airflow/.local/lib/python3.7/site-packages/requests/models.py", line 1021, in raise_for_status
    raise HTTPError(http_error_msg, response=self)
requests.exceptions.HTTPError: 409 Client Error: Conflict for url: http+docker://localhost/v1.48/containers/create?name=pipeline_extract_idx

The above exception was the direct cause of the following exception:

Traceback (most recent call last):
  File "/home/airflow/.local/lib/python3.7/site-packages/airflow/providers/docker/operators/docker.py", line 478, in execute
    return self._run_image()
  File "/home/airflow/.local/lib/python3.7/site-packages/airflow/providers/docker/operators/docker.py", line 351, in _run_image
    return self._run_image_with_mounts(self.mounts, add_tmp_variable=False)
  File "/home/airflow/.local/lib/python3.7/site-packages/airflow/providers/docker/operators/docker.py", line 393, in _run_image_with_mounts
    hostname=self.hostname,
  File "/home/airflow/.local/lib/python3.7/site-packages/docker/api/container.py", line 431, in create_container
    return self.create_container_from_config(config, name, platform)
  File "/home/airflow/.local/lib/python3.7/site-packages/docker/api/container.py", line 448, in create_container_from_config
    return self._result(res, True)
  File "/home/airflow/.local/lib/python3.7/site-packages/docker/api/client.py", line 274, in _result
    self._raise_for_status(response)
  File "/home/airflow/.local/lib/python3.7/site-packages/docker/api/client.py", line 270, in _raise_for_status
    raise create_api_error_from_http_exception(e) from e
  File "/home/airflow/.local/lib/python3.7/site-packages/docker/errors.py", line 39, in create_api_error_from_http_exception
    raise cls(e, response=response, explanation=explanation) from e
docker.errors.APIError: 409 Client Error for http+docker://localhost/v1.48/containers/create?name=pipeline_extract_idx: Conflict ("Conflict. The container name "/pipeline_extract_idx" is already in use by container "8f0d0910d1d3af514732d3fa3f550f650362152af632a8e7189a0766e6396912". You have to remove (or rename) that container to be able to reuse that name.")
[2025-06-17T10:40:32.066+0000] {taskinstance.py:1350} INFO - Marking task as FAILED. dag_id=idx_pipeline, task_id=extract_idx, execution_date=20250617T103841, start_date=20250617T104031, end_date=20250617T104032
[2025-06-17T10:40:32.097+0000] {standard_task_runner.py:109} ERROR - Failed to execute job 69 for task extract_idx (409 Client Error for http+docker://localhost/v1.48/containers/create?name=pipeline_extract_idx: Conflict ("Conflict. The container name "/pipeline_extract_idx" is already in use by container "8f0d0910d1d3af514732d3fa3f550f650362152af632a8e7189a0766e6396912". You have to remove (or rename) that container to be able to reuse that name."); 154)
[2025-06-17T10:40:32.137+0000] {local_task_job_runner.py:225} INFO - Task exited with return code 1
[2025-06-17T10:40:32.191+0000] {taskinstance.py:2653} INFO - 0 downstream tasks scheduled from follow-on schedule check
